Workbook

Sheet Read Me
A1: Hasiru Agro: New E-Commerce Website, Data Collection Sheet
A2: Prepared by WODO for the Hasiru Agro team. Please fill the yellow cells in every tab.
A4: Purpose | B4: The new website needs product, recommendation, calculator and delivery data to power the features in the SRS. This workbook lists every feature, the data it needs, and gives a place to fill it.
A5: Colour key
B6: Green cells: already taken from the old hasiruagro.com shop. Please check and correct.
B7: Yellow cells: please fill. These are new and required for the new features.
B8: Blue cells: calculated automatically. Do not edit.
A9: Tabs
A10: 1. Feature Map | B10: Every website feature, the SRS section it comes from, and which tab/columns feed it.
A11: 2. Plants | B11: All 193 plants from the old shop, pre-filled. Add new columns (category, weight, spacing, model role, etc.). Add new plants at the bottom.
A12: 3. Input Products | B12: Compost, vermicompost, biochar, seeds, liquid fertiliser, bio-pesticide. New, please fill fully.
A13: 4. Recommendation Models | B13: Commercial, Food Forest, Miyawaki: which plants, their role (main/host/biomass), spacing and quantities.
A14: 5. Calculators | B14: Formulas for the plant, compost, biochar, vermicompost and seed calculators.
A15: 6. Logistics | B15: Vehicles, capacity, delivery zones, Bengaluru schedule, outstation rates, packing charges.
A16: 7. Content & Policies | B16: Checklist of text, logos, photos, videos, testimonials, client and project data.
A17: 8. Category Map | B17: Proposed mapping of old shop categories to the new Timber / Fruiting / Other structure.
A18: Notes
A19: Pricing | B19: Each plant has a normal price (below its bulk quantity) and a bulk price. The bulk quantity differs per plant: e.g. 50 for big trees like mango, 200 for small shrubs. Fill both columns in the Plants tab. Old Regular / Sale / Offline prices are shown for reference.
A20: Sizes | B20: Plant sizes: do any plants come in more than one size (e.g. 1.5 ft and 6 ft)? If yes, add one row per size and use the same Parent Name.
A21: Weights | B21: Weights: every plant currently shows 1 kg / 70 cm (placeholder). Real weight and pot/bag size are needed for delivery and truck-capacity calculation.
A22: GST | B22: GST: please confirm HSN and GST % per product (plants are usually HSN 0602 at 0%, vermicompost/compost 3101 at 5%; confirm with your CA).

Sheet Feature Map
A1: Feature Map
A2: Each website feature and the data needed to build it.
A4: # | B4: Feature | C4: Where on site | D4: SRS ref | E4: What it does | F4: Data needed from Hasiru Agro | G4: Filled in tab | H4: Priority | I4: Status
A5: 1 | B5: Two-path entry (I know what I want / Help me choose) | C5: Home hero | D5: 1.1 | E5: Splits shoppers into direct shop vs guided recommendation. | F5: Banner image, headline copy. | G5: Content & Policies | H5: Must | I5: Pending
A6: 2 | B6: Best sellers carousel (quick-commerce style) | C6: Home | D6: 1.2 | E6: Horizontal swipe cards with add to cart. | F6: Best seller flag, image, height, exposure, rain, temperature, packet weight, price, offer price, availability. | G6: Plants | H6: Must | I6: Pending
A7: 3 | B7: Simple plant calculator (plants per acre) | C7: Home + floating on Shop | D7: 1.2A, 3.4 | E7: 43,560 / (spacing L x W ft) = plants per acre. | F7: Recommended spacing L and W (ft) per plant. Confirm formula and any buffer % (note '43,560 x 3 / 100' in sketch). | G7: Plants, Calculators | H7: Must | I7: Pending
A8: 4 | B8: Input products carousel | C8: Home | D8: 1.3 | E8: Compost, seeds, biochar, liquid fertiliser, bio-pesticide cards. | F8: Full input product list with pack sizes and prices. | G8: Input Products | H8: Must | I8: Pending
A9: 5 | B9: Compost calculator | C9: Home | D9: 1.4 | E9: Plants selected -> estimated compost -> recommended product -> add to cart. | F9: Compost kg per plant (by plant size/type), product to recommend. | G9: Calculators, Plants | H9: Must | I9: Pending
A10: 6 | B10: Incubated by UAS Dharwad band | C10: Home + About | D10: 1.5, 26 | E10: Running band of institutional logos. | F10: Logos (UAS Dharwad, Startup India, MSME, others), approved wording, links. | G10: Content & Policies | H10: Must | I10: Pending
A11: 7 | B11: DIY / Learn how videos | C11: Home + Recommendation page | D11: 1.6, 8 | E11: Video carousel; model-specific planting video. | F11: Video URLs, titles, thumbnails, category, linked model. | G11: Content & Policies | H11: Must | I11: Pending
A12: 8 | B12: Why Choose Us | C12: Home + own page | D12: 1.7, 2, 24 | E12: Authenticity, expertise, results, delivery to farm. | F12: Verified numbers: acres, farms, customers, projects, plants planted. | G12: Content & Policies | H12: Must | I12: Pending
A13: 9 | B13: Testimonials | C13: Home | D13: 1.8 | E13: Horizontal review cards. | F13: Name, location, photo, review, rating, farm/project info. | G13: Content & Policies | H13: Must | I13: Pending
A14: 10 | B14: Plant shop with categories | C14: Shop | D14: 3.1-3.3 | E14: Timber / Fruiting / Other grid with qty +/-. | F14: Final category per plant, description, price, stock, availability. | G14: Plants, Category Map | H14: Must | I14: Pending
A15: 11 | B15: Product attributes | C15: Product page | D15: 1.2, 3.2 | E15: Spec table on each plant. | F15: Height, exposure, rain, temperature, type, bearing time, yield, spacing, harvest season. | G15: Plants | H15: Must | I15: Pending
A16: 12 | B16: Help me choose wizard | C16: Popup | D16: 4.1-4.3 | E16: Land size (acre / sq ft), location (map/search), purpose, name + phone OTP, Generate. | F16: Purposes list (Commercial, Food Forest, Miyawaki, others). Any location-based rules (which plants suit which district/climate). | G16: Recommendation Models | H16: Must | I16: Pending
... A33: 29 | B33: Admin dashboard + inventory | C33: Admin | D33: 30-33 | E33: Sales, regions, best sellers, low stock, enquiries, orders. | F33: Low-stock threshold per product; current stock. | G33: Plants, Input Products | H33: Must | I33: Pending

Sheet Plants
A1: Plants: Product Master
A2: Green = from old shop (please verify). Yellow = please fill. Blue = auto. One row per plant per size.
A4: SKU | B4: Plant Name | C4: Kannada Name | D4: Old Category | E4: New Category | F4: Sub-category | G4: Show on site? | H4: Best Seller? | I4: Plant Type (Grafted / Seeded / Air layered...) | J4: Size / Variant (e.g. 2 ft, 6 ft) | K4: Plant Height at Sale (ft) | L4: Pot / Bag Size | M4: Weight per Plant incl. pot (kg) | N4: Plants per Truck (smallest vehicle) | O4: Regular Price (Rs) | P4: Sale Price (Rs) | Q4: Offline Price (Rs) | R4: Bulk Starts at Qty (e.g. 50 for big trees, 200 for shrubs) | S4: Bulk Price per Plant (Rs) | T4: Current Stock | U4: Low Stock Alert at | V4: Availability | W4: HSN Code | X4: GST % | Y4: Spacing L (ft) | Z4: Spacing W (ft) | AA4: Plants per Acre | AB4: Spacing (old text) | AC4: Exposure | AD4: Rain / Water Need | AE4: Temperature | AF4: Growth Habit | AG4: Bearing Time | AH4: Yield per Tree | AI4: Harvest Season | AJ4: Fruit Size | AK4: Suitable Models (Commercial / Food Forest / Miyawaki) | AL4: Role in Model (Main / Host / Biomass) | AM4: Forest Layer (Canopy / Sub-canopy / Shrub...) | AN4: Vermicompost per Plant (kg) | AO4: Biochar per Plant (kg) | AP4: Compost per Plant (kg) | AQ4: Districts / Zones NOT suitable | AR4: Image URL (old site) | AS4: New Photo Needed? | AT4: Notes / Corrections
A5: HA001 | B5: Guava KG | D5: Desi Fruits | E5: Fruiting Trees | F5: Desi | G5: Yes | H5: No | I5: Air layered | O5: 640 | P5: 450 | Q5: 180 | T5: 0 | V5: Out of Stock | Y5: 18 | Z5: 18 | AA5: =IF(AND(N(Y5)>0,N(Z5)>0),ROUND(43560/(Y5*Z5),0),"") | AB5: 18ft x 18ft | AC5: Full sun | AE5: 20°C to 40 °C | AF5: Medium sized tree | AG5: 2 years | AH5: 350Kg to 400Kg | AI5: Round the year | AJ5: 400gms to 1000gms | AR5: https://hasiruagro.com/wp-content/uploads/2023/08/Guava-KG-Fruit-fruit-image-Hasiruagro.jpg
A6: HA002 | B6: GuavaTaiwan Pink | D6: Desi Fruits | E6: Fruiting Trees | F6: Desi | G6: Yes | H6: No | I6: Air layered | O6: 600 | P6: 420 | Q6: 60 | T6: 0 | V6: Out of Stock | Y6: 18 | Z6: 18 | AA6: =IF(AND(N(Y6)>0,N(Z6)>0),ROUND(43560/(Y6*Z6),0),"") | AB6: 18ft x 18ft | AC6: Full sun | AE6: 20°C to 40 °C | AF6: Medium sized tree | AG6: 2 years | AH6: 30Kg to 70kg | AI6: Round the year | AJ6: 150gms to 200gms | AR6: https://hasiruagro.com/wp-content/uploads/2023/08/taiwan-pink-guava-fruit-fruit-image-Hasiruagro.jpg
A7: HA003 | B7: Abiu (Seeded) | D7: Exotic fruits | E7: Fruiting Trees | F7: Exotic | G7: Yes | H7: No | I7: Seeded | O7: 1560 | P7: 1090 | Q7: 680 | T7: 0 | V7: Out of Stock | AA7: =IF(AND(N(Y7)>0,N(Z7)>0),ROUND(43560/(Y7*Z7),0),"") | AC7: Full sun | AE7: 16°C to 35 °C | AF7: Medium tree | AG7: 2 years | AH7: 100Kgs to 150Kgs | AI7: February to October | AJ7: 300gms to 600gms | AR7: https://hasiruagro.com/wp-content/uploads/2023/08/Abiu-Fruit-Plantplant-with-fruit-image-Hasiruagro.jpg
A8: HA004 | B8: Achachiru | D8: Exotic fruits | E8: Fruiting Trees | F8: Exotic | G8: Yes | H8: No | I8: Grafted | O8: 1540 | P8: 1080 | Q8: 830 | T8: 30 | V8: Available | AA8: =IF(AND(N(Y8)>0,N(Z8)>0),ROUND(43560/(Y8*Z8),0),"") | AC8: Full shade | AE8: 16°C to 35 °C | AF8: Medium tree | AG8: 4 years | AH8: 75Kgs to 150Kgs | AI8: October to May | AJ8: 100gms to 150gms | AR8: https://hasiruagro.com/wp-content/uploads/2023/08/Achachairuplant-with-fruit-image-Hasiruagro.jpg
A9: HA005 | B9: Agarwood | D9: Forestry | E9: Timber Trees | G9: Yes | H9: Yes | I9: Seeded | O9: 400 | P9: 280 | Q9: 60 | T9: 0 | V9: Out of Stock | Y9: 15 | Z9: 15 | AA9: =IF(AND(N(Y9)>0,N(Z9)>0),ROUND(43560/(Y9*Z9),0),"") | AB9: 15ft x 15ft | AC9: Full sun | AE9: 20°C to 35°C | AF9: 20ft to 30ft tall | AG9: 12 years | AH9: 5 to 8 kilograms of heartwood. | AR9: https://hasiruagro.com/wp-content/uploads/2023/07/Agarwood-F.jpg
A10: HA006 | B10: All season Jackfruit | D10: Desi Fruits | E10: Fruiting Trees | F10: Desi | G10: Yes | H10: No | I10: Grafted | O10: 1325 | P10: 530 | Q10: 180 | T10: 0 | V10: Out of Stock | Y10: 20 | Z10: 20 | AA10: =IF(AND(N(Y10)>0,N(Z10)>0),ROUND(43560/(Y10*Z10),0),"") | AB10: 20ft x 20ft | AC10: Open sun | AE10: 20°C to 40 °C | AF10: Big tree | AG10: 2 years | AH10: 150 to 200 fruits | AI10: Round the year | AJ10: Medium to Large | AR10: https://hasiruagro.com/wp-content/uploads/2023/07/All-season-Jackfruit-fruit-image.webp
A11: HA007 | B11: All Season Lemon | D11: Desi Fruits | E11: Fruiting Trees | F11: Desi | G11: Yes | H11: No | I11: Grafted | O11: 440 | P11: 310 | Q11: 150 | T11: 1 | V11: Available | Y11: 10 | Z11: 10 | AA11: =IF(AND(N(Y11)>0,N(Z11)>0),ROUND(43560/(Y11*Z11),0),"") | AB11: 10ft x 10ft | AC11: Open sun | AE11: 20°C to 40 °C | AF11: Small tree | AG11: 2 years | AH11: 80Kg to 100Kg | AI11: Year round | AJ11: 30gms to 50gms | AR11: https://hasiruagro.com/wp-content/uploads/2023/07/All-Season-Lemon-fruit-fruit-ima.webp
A12: HA008 | B12: All Season Mango | D12: Desi Fruits | E12: Fruiting Trees | F12: Desi | G12: Yes | H12: Yes | I12: Grafted | O12: 700 | P12: 490 | Q12: 220 | T12: 0 | V12: Out of Stock | Y12: 18 | Z12: 18 | AA12: =IF(AND(N(Y12)>0,N(Z12)>0),ROUND(43560/(Y12*Z12),0),"") | AB12: 18ft x 18ft | AC12: Open sun | AE12: 20°C to 40 °C | AF12: Medium sized tree | AG12: 2 years | AH12: 200 to 250 fruits | AI12: Year round | AJ12: 100gm to 150gm | AR12: https://hasiruagro.com/wp-content/uploads/2023/08/All-Season-Mango-Fruit-image-Hasiruagro.jpg
A13: HA009 | B13: All spices | D13: Spices | E13: Other Plants | F13: Spices | G13: Yes | H13: Yes | I13: Seeded | O13: 440 | P13: 310 | Q13: 120 | T13: 0 | V13: Out of Stock | AA13: =IF(AND(N(Y13)>0,N(Z13)>0),ROUND(43560/(Y13*Z13),0),"") | AB13: Medium size tree | AC13: Full sun or Partial shade | AE13: 16°C to 35°C | AF13: Medium size tree | AG13: 3 years | AH13: 20-25 Kg dry berries | AI13: June to September | AJ13: 1gm to 2gms | AR13: https://hasiruagro.com/wp-content/uploads/2023/07/All-Spices-F.jpg
A14: HA0010 | B14: Allahabad Safeda Guava | D14: Desi Fruits | E14: Fruiting Trees | F14: Desi | G14: Yes | H14: No | I14: Air layered | O14: 400 | P14: 280 | Q14: 100 | T14: 0 | V14: Out of Stock | Y14: 18 | Z14: 18 | AA14: =IF(AND(N(Y14)>0,N(Z14)>0),ROUND(43560/(Y14*Z14),0),"") | AB14: 18ft x 18ft | AC14: Full sun | AE14: 20°C to 40 °C | AF14: Medium sized tree | AG14: 2 years | AH14: 30Kg to 70kg | AI14: Round the year | AJ14: 150gms to 200gms | AR14: https://hasiruagro.com/wp-content/uploads/2023/08/allahabad-safeda-guava-fruit-fruit-image-Hasiruagro.jpg
A15: HA0011 | B15: Alphonoso Mango | D15: Desi Fruits | E15: Fruiting Trees | F15: Desi | G15: Yes | H15: Yes | I15: Grafted | O15: 700 | P15: 490 | Q15: 350 | T15: 168 | V15: Available | Y15: 18 | Z15: 18 | AA15: =IF(AND(N(Y15)>0,N(Z15)>0),ROUND(43560/(Y15*Z15),0),"") | AB15: 18ft x 18ft | AC15: Open sun | AE15: 20°C to 40 °C | AF15: Medium sized tree | AG15: 2 years | AH15: 300 to 500 fruits | AI15: April to August | AJ15: 200gm to 250gm | AR15: https://hasiruagro.com/wp-content/uploads/2023/08/Alphonso-Mango-S.jpg
A16: HA0012 | B16: American Red Palmar mango | D16: Exotic fruits | E16: Fruiting Trees | F16: Exotic | G16: Yes | H16: Yes | I16: Grafted | O16: 700 | P16: 490 | Q16: 250 | T16: 0 | V16: Out of Stock | AA16: =IF(AND(N(Y16)>0,N(Z16)>0),ROUND(43560/(Y16*Z16),0),"") | AC16: Full sun | AE16: 20°C to 40 °C | AF16: Medium to big tree | AG16: 2 years | AH16: 80Kgs to 100Kgs per tree | AI16: March to June | AJ16: 150gms to 200gms | AR16: https://hasiruagro.com/wp-content/uploads/2023/08/American-Red-Palmar-1.jpg
A17: HA0013 | B17: Amla (Grafted) | D17: Desi Fruits | E17: Fruiting Trees | F17: Desi | G17: Yes | H17: No | I17: Grafted | O17: 900 | P17: 630 | Q17: 250 | T17: 0 | V17: Out of Stock | Y17: 20 | Z17: 20 | AA17: =IF(AND(N(Y17)>0,N(Z17)>0),ROUND(43560/(Y17*Z17),0),"") | AB17: 20ft x 20ft | AC17: Open sun | AE17: 20°C to 40 °C | AF17: Big tree | AG17: 5 yeras | AH17: 50Kg to 70Kg | AI17: September to December | AJ17: 60gm to 70gm | AR17: https://hasiruagro.com/wp-content/uploads/2023/08/Amla-Grafted-fruit-image-Hasiruagro.jpg
A18: HA0014 | B18: Amla (Seeded) | D18: Desi Fruits | E18: Fruiting Trees | F18: Desi | G18: Yes | H18: No | I18: Seeded | O18: 700 | P18: 490 | Q18: 100 | T18: 6 | V18: Available | Y18: 20 | Z18: 20 | AA18: =IF(AND(N(Y18)>0,N(Z18)>0),ROUND(43560/(Y18*Z18),0),"") | AB18: 20ft x 20ft | AC18: Open sun | AE18: 20°C to 40 °C | AF18: Big tree | AG18: 5 yeras | AH18: 50Kg to 70Kg | AI18: September to December | AJ18: 60gm to 70gm | AR18: https://hasiruagro.com/wp-content/uploads/2023/07/Amla-F.jpg
A19: HA0015 | B19: Amrapali Mango | D19: Desi Fruits | E19: Fruiting Trees | F19: Desi | G19: Yes | H19: No | I19: Grafted | O19: 540 | P19: 380 | Q19: 200 | T19: 0 | V19: Out of Stock | Y19: 18 | Z19: 18 | AA19: =IF(AND(N(Y19)>0,N(Z19)>0),ROUND(43560/(Y19*Z19),0),"") | AB19: 18ft x 18ft | AC19: Open sun | AE19: 20°C to 40 °C | AF19: Medium sized tree | AG19: 2 years | AH19: 200 to 250 fruits | AI19: Year round | AJ19: 100gm to 150gm | AR19: https://hasiruagro.com/wp-content/uploads/2023/08/Amrapali-MangoFruit-image-Hasiruagro.jpg
A20: HA0016 | B20: Diana Anjeer Fig Plants | D20: Exotic fruits | E20: Fruiting Trees | F20: Exotic | G20: Yes | H20: No | I20: Grafted | O20: 500 | P20: 350 | Q20: 150 | T20: 0 | V20: Out of Stock | AA20: =IF(AND(N(Y20)>0,N(Z20)>0),ROUND(43560/(Y20*Z20),0),"") | AC20: Full sun | AE20: 20°C to 40 °C | AF20: Medium to big tree | AG20: 2 years | AH20: 180 to 360 fruits per tree | AI20: Febraury to August | AJ20: 50gms to 70gms | AR20: https://hasiruagro.com/wp-content/uploads/2024/03/Diana-Anjeer-Fig-Plants-Hasiruagro.jpg
A21: HA0017 | B21: Appe midi Mango | D21: Desi Fruits | E21: Fruiting Trees | F21: Desi | G21: Yes | H21: No | I21: Grafted | O21: 660 | P21: 460 | Q21: 250 | T21: 0 | V21: Out of Stock | Y21: 18 | Z21: 18 | AA21: =IF(AND(N(Y21)>0,N(Z21)>0),ROUND(43560/(Y21*Z21),0),"") | AB21: 18ft x 18ft | AC21: Open sun | AE21: 20°C to 40 °C | AF21: Medium sized tree | AG21: 2 years | AH21: 300 to 500 fruits | AI21: April to August | AJ21: 50gm to 100gm | AR21: https://hasiruagro.com/wp-content/uploads/2023/08/Appe-Midi-Mango-F.jpg
A22: HA0018 | B22: Apple Ana | D22: Desi Fruits | E22: Fruiting Trees | F22: Desi | G22: Yes | H22: No | I22: Grafted | O22: 560 | P22: 390 | Q22: 180 | T22: 0 | V22: Out of Stock | Y22: 15 | Z22: 15 | AA22: =IF(AND(N(Y22)>0,N(Z22)>0),ROUND(43560/(Y22*Z22),0),"") | AB22: 15ft x 15ft | AC22: Full sun | AE22: 20°C to 30 °C | AF22: Medium sized tree | AG22: 3 years | AH22: 50Kg to 80Kg | AI22: April to July | AJ22: 80gms to 120gms | AR22: https://hasiruagro.com/wp-content/uploads/2023/08/Apple-AnaFruit-image-Hasiruagro.jpg
A23: HA0019 | B23: Apple Ber Ball sundari | D23: Exotic fruits | E23: Fruiting Trees | F23: Exotic | G23: Yes | H23: No | I23: Seeded | O23: 280 | P23: 195 | Q23: 60 | T23: 47 | V23: Available | AA23: =IF(AND(N(Y23)>0,N(Z23)>0),ROUND(43560/(Y23*Z23),0),"") | AC23: Full sun | AE23: 20°C to 40 °C | AF23: Small Tree | AG23: 3 years | AH23: 50Kgs to 70Kgs per tree | AI23: Alternative seasons | AJ23: 50gms to 70gms | AR23: https://hasiruagro.com/wp-content/uploads/2023/08/Apple-Ber-Ball-sundariPlant-with-Fruit-image-Hasiruagro.jpg
A24: HA0020 | B24: Apple Ber Kashmiri | D24: Exotic fruits | E24: Fruiting Trees | F24: Exotic | G24: Yes | H24: No | I24: Seeded | O24: 280 | P24: 195 | Q24: 60 | T24: 47 | V24: Available | AA24: =IF(AND(N(Y24)>0,N(Z24)>0),ROUND(43560/(Y24*Z24),0),"") | AC24: Full sun | AE24: 20°C to 40 °C | AF24: Small Tree | AG24: 3 years | AH24: 50Kgs to 70Kgs per tree | AI24: Alternative seasons | AJ24: 50gms to 70gms | AR24: https://hasiruagro.com/wp-content/uploads/2023/08/Apple-Ber-KashmiriPlant-with-Fruit-image-Hasiruagro.jpg
A25: HA0021 | B25: Apple Dorset | D25: Desi Fruits | E25: Fruiting Trees | F25: Desi | G25: Yes | H25: No | I25: Grafted | O25: 560 | P25: 390 | Q25: 180 | T25: 0 | V25: Out of Stock | Y25: 15 | Z25: 15 | AA25: =IF(AND(N(Y25)>0,N(Z25)>0),ROUND(43560/(Y25*Z25),0),"") | AB25: 15ft x 15ft | AC25: Full sun | AE25: 18°C to 35 °C | AF25: Medium sized tree | AG25: 3 years | AH25: 50Kg to 80Kg | AI25: April to July | AJ25: 80gms to 120gms | AR25: https://hasiruagro.com/wp-content/uploads/2023/08/Apple-DorsetFruit-image-Hasiruagro.jpg
A26: HA0022 | B26: Apple Hariman-99 | D26: Desi Fruits | E26: Fruiting Trees | F26: Desi | G26: Yes | H26: No | I26: Grafted | O26: 600 | P26: 420 | Q26: 450 | T26: 0 | V26: Out of Stock | Y26: 15 | Z26: 15 | AA26: =IF(AND(N(Y26)>0,N(Z26)>0),ROUND(43560/(Y26*Z26),0),"") | AB26: 15ft x 15ft | AC26: Full sun | AE26: 20°C to 35 °C | AF26: Medium sized tree | AG26: 3 years | AH26: 50Kg to 100Kg | AI26: April to July | AJ26: 80gms to 120gms | AR26: https://hasiruagro.com/wp-content/uploads/2023/08/Hariman-Apple-F.jpg
A27: HA0023 | B27: Apple litchi | D27: Desi Fruits | E27: Fruiting Trees | F27: Desi | G27: Yes | H27: No | I27: Grafted | O27: 600 | P27: 420 | Q27: 200 | T27: 0 | V27: Out of Stock | Y27: 25 | Z27: 25 | AA27: =IF(AND(N(Y27)>0,N(Z27)>0),ROUND(43560/(Y27*Z27),0),"") | AB27: 25ft x 25ft | AC27: Full sun | AE27: 15°C to 38°C | AF27: Medium sized tree | AG27: 3 years | AH27: 80Kg to 150Kg | AI27: April to July | AJ27: 50gms to 70gms | AR27: https://hasiruagro.com/wp-content/uploads/2023/08/Apple-litchiFruit-image-Hasiruagro.jpg
A28: HA0024 | B28: Apricot | D28: Exotic fruits | E28: Fruiting Trees | F28: Exotic | G28: Yes | H28: No | I28: Grafted | O28: 700 | P28: 490 | Q28: 250 | T28: 0 | V28: Out of Stock | AA28: =IF(AND(N(Y28)>0,N(Z28)>0),ROUND(43560/(Y28*Z28),0),"") | AC28: Full sun | AE28: 16°C to 35 °C | AF28: Medium to big tree | AG28: 4 years | AH28: 70Kgs to 90Kgs per tree | AI28: April to August | AJ28: 70gms to 100gms | AR28: https://hasiruagro.com/wp-content/uploads/2023/08/ApricotPlant-with-Fruit-image-Hasiruagro.jpg
A29: HA0025 | B29: Areca Bukkambudi | D29: Plantation | E29: Other Plants | F29: Plantation | G29: Yes | H29: No | I29: Seeded | O29: 320 | P29: 225 | Q29: 60 | T29: 348 | V29: Available | Y29: 11 | Z29: 11 | AA29: =IF(AND(N(Y29)>0,N(Z29)>0),ROUND(43560/(Y29*Z29),0),"") | AB29: 11ft x 11ft | AC29: Full sun | AE29: 20°C to 35°C | AF29: 40ft to 60ft | AG29: 4 years | AH29: 200 to 400 ripe nuts | AI29: Alternative seasonsAugust and September in plain land regions and in malnad areas during December and January. | AR29: https://hasiruagro.com/wp-content/uploads/2023/08/Areca-BukkambudiFruit-image-Hasiruagro.jpg
A30: HA0026 | B30: Areca Tirthalli | D30: Plantation | E30: Other Plants | F30: Plantation | G30: Yes | H30: No | I30: Seeded | O30: 320 | P30: 225 | Q30: 60 | T30: 68 | V30: Available | Y30: 11 | Z30: 11 | AA30: =IF(AND(N(Y30)>0,N(Z30)>0),ROUND(43560/(Y30*Z30),0),"") | AB30: 11ft x 11ft | AC30: Full sun | AE30: 20°C to 35°C | AF30: 40ft to 60ft | AG30: 4 years | AH30: 200 to 400 ripe nuts | AI30: Alternative seasonsAugust and September in plain land regions and in malnad areas during December and January. | AR30: https://hasiruagro.com/wp-content/uploads/2023/08/Areca-TirthalliFruit-image-Hasiruagro.jpg
A31: HA0027 | B31: Avocado coorg variety | D31: Exotic fruits | E31: Fruiting Trees | F31: Exotic | G31: Yes | H31: No | I31: Grafted | O31: 875 | P31: 350 | Q31: 150 | T31: 0 | V31: Out of Stock | Y31: 18 | Z31: 18 | AA31: =IF(AND(N(Y31)>0,N(Z31)>0),ROUND(43560/(Y31*Z31),0),"") | AB31: 18ft x 18ft | AC31: Full sun (Can tolerate partial shade | AE31: 16⁰C – 42⁰C | AF31: Medium to large tree (30ft to 60ft tall) | AG31: 2.5 years after planting | AH31: 30Kgs to 50Kgs | AI31: June to October | AJ31: 150gms to 250gms | AR31: https://hasiruagro.com/wp-content/uploads/2023/07/Avocado-coorg-varietyFruit-image-Hasiruagro.webp
A32: HA0028 | B32: Hass Avocado Plant | D32: Exotic fruits | E32: Fruiting Trees | F32: Exotic | G32: Yes | H32: No | I32: Grafted | O32: 2800 | P32: 1120 | Q32: 700 | T32: 0 | V32: Out of Stock | Y32: 18 | Z32: 18 | AA32: =IF(AND(N(Y32)>0,N(Z32)>0),ROUND(43560/(Y32*Z32),0),"") | AB32: 18ft x 18ft | AC32: Full sun (Can tolerate partial shade | AE32: 16⁰C – 35⁰C | AF32: Medium to large tree (30ft to 60ft tall) | AG32: 2.5 years after planting | AH32: 120 Kgs to160 Kgs | AI32: June to Otober | AJ32: 150gms to 250gms | AR32: https://hasiruagro.com/wp-content/uploads/2023/07/avocado-haas-fruit-fruit-image-Hasiruagro.webp
A33: HA0029 | B33: Grafted Mexican Purple Avocado Plant | D33: Exotic fruits | E33: Fruiting Trees | F33: Exotic | G33: Yes | H33: No | I33: Grafted | O33: 1575 | P33: 630 | Q33: 350 | T33: 0 | V33: Out of Stock | Y33: 18 | Z33: 18 | AA33: =IF(AND(N(Y33)>0,N(Z33)>0),ROUND(43560/(Y33*Z33),0),"") | AB33: 18ft x 18ft | AC33: Full sun (Can tolerate partial shade | AE33: 20⁰C – 42⁰C | AF33: Medium to large tree (30ft to 60ft tall) | AG33: 2.5 years after planting | AH33: 180kgs to 200kgs | AI33: June to October | AJ33: 200gms to 300gms | AR33: https://hasiruagro.com/wp-content/uploads/2023/07/Grafted-Mexican-Purple-Avocado-Hasiruagro.webp
A34: HA0030 | B34: Shiny green Avocado | D34: Exotic fruits | E34: Fruiting Trees | F34: Exotic | G34: Yes | H34: No | I34: Grafted | O34: 1575 | P34: 630 | Q34: 350 | T34: 0 | V34: Out of Stock | Y34: 18 | Z34: 18 | AA34: =IF(AND(N(Y34)>0,N(Z34)>0),ROUND(43560/(Y34*Z34),0),"") | AB34: Spacing: 18ft x 18ft | AC34: Full sun (Can tolerate partial shade | AE34: 16°C to 40°C | AF34: Growth: Medium to large tree (30ft to 60ft tall) | AG34: 2.5 years after planting | AH34: 180Kgs to 200Kgs | AI34: Harvesting: June to October | AJ34: 150gms to 250gms | AR34: https://hasiruagro.com/wp-content/uploads/2023/07/Grafted-Shiny-Green-Avocado-Hasiruagro.webp
A35: HA0031 | B35: Avocado TKD-1 | D35: Exotic fruits | E35: Fruiting Trees | F35: Exotic | G35: Yes | H35: No | I35: Grafted | O35: 1575 | P35: 630 | Q35: 350 | T35: 0 | V35: Out of Stock | Y35: 18 | Z35: 18 | AA35: =IF(AND(N(Y35)>0,N(Z35)>0),ROUND(43560/(Y35*Z35),0),"") | AB35: 18ft x 18ft | AC35: Full sun (Can tolerate partial shade | AE35: 16⁰C – 35⁰C | AF35: Medium to large tree (30ft to 60ft tall) | AG35: 2.5 years after planting | AH35: 250 Kgs to300 Kgs | AI35: June to Otober | AJ35: 150gms to 250gms | AR35: https://hasiruagro.com/wp-content/uploads/2023/07/Avocado-TKD-1Fruit-image-Hasiruagro.webp
A36: HA0032 | B36: B-1 Musambi Malta | D36: Desi Fruits | E36: Fruiting Trees | F36: Desi | G36: Yes | H36: No | I36: Grafted | O36: 500 | P36: 350 | Q36: 200 | T36: 250 | V36: Available | Y36: 18 | Z36: 18 | AA36: =IF(AND(N(Y36)>0,N(Z36)>0),ROUND(43560/(Y36*Z36),0),"") | AB36: 18ft x 18ft | AC36: Open sun | AE36: 20°C to 40 °C | AF36: Medium sized tree | AG36: 2 years | AH36: 60Kg to 100Kg | AI36: April to MayAugust to September | AJ36: 70 gm to 150gm | AR36: https://hasiruagro.com/wp-content/uploads/2023/08/B-1-Musambi-MaltaFruit-image-Hasiruagro.jpg
A37: HA0033 | B37: Badami Mango | D37: Desi Fruits | E37: Fruiting Trees | F37: Desi | G37: Yes | H37: No | I37: Grafted | O37: 700 | P37: 490 | Q37: 250 | T37: 122 | V37: Available | Y37: 18 | Z37: 18 | AA37: =IF(AND(N(Y37)>0,N(Z37)>0),ROUND(43560/(Y37*Z37),0),"") | AB37: 18ft x 18ft | AC37: Open sun | AE37: 20°C to 40 °C | AF37: Medium sized tree | AG37: 2 years | AH37: 300 to 500 fruits | AI37: April to August | AJ37: 200gm to 250gm | AR37: https://hasiruagro.com/wp-content/uploads/2023/08/Mango-Badami-Fruit-fruit-image-Hasiruagro.jpg
A38: HA0034 | B38: Banana Sapota | D38: Exotic fruits | E38: Fruiting Trees | F38: Exotic | G38: Yes | H38: No | I38: Grafted | O38: 1400 | P38: 980 | Q38: 200 | T38: 0 | V38: Out of Stock | AA38: =IF(AND(N(Y38)>0,N(Z38)>0),ROUND(43560/(Y38*Z38),0),"") | AC38: Full sun | AE38: 20°C to 40 °C | AF38: Medium to big tree | AG38: 3 years | AH38: 2500 to 3000 fruits per tree | AI38: Alternate seasons | AJ38: 150gms to 200gms | AR38: https://hasiruagro.com/wp-content/uploads/2023/08/banana-sapota-fruit-fruit-image-Hasiruagro.jpg
A39: HA0035 | B39: Bangkok Mango | D39: Exotic fruits | E39: Fruiting Trees | F39: Exotic | G39: Yes | H39: No | I39: Grafted | O39: 800 | P39: 560 | Q39: 200 | T39: 0 | V39: Out of Stock | AA39: =IF(AND(N(Y39)>0,N(Z39)>0),ROUND(43560/(Y39*Z39),0),"") | AC39: Full sun | AE39: 20°C to 35°C | AF39: Small to medium sized tree | AG39: 3 years | AH39: 100Kgs to 150Kgs per tree | AI39: March to June | AJ39: 500gm to 700gm | AR39: https://hasiruagro.com/wp-content/uploads/2023/08/Bangkok-Mango.jpg
A40: HA0036 | B40: Barbados Cherry | D40: Exotic fruits | E40: Fruiting Trees | F40: Exotic | G40: Yes | H40: No | I40: Seeded | O40: 560 | P40: 390 | Q40: 180 | T40: 0 | V40: Out of Stock | AA40: =IF(AND(N(Y40)>0,N(Z40)>0),ROUND(43560/(Y40*Z40),0),"") | AC40: Full sun | AE40: 16°C to 35 °C | AF40: Small tree | AG40: 3 years | AH40: 20Kgs to 30Kgs per tree | AI40: November to March | AJ40: 70gms to 100gms | AR40: https://hasiruagro.com/wp-content/uploads/2023/08/Barbados-CherryFruit-image-Hasiruagro.jpg
A41: HA0037 | B41: Bhadoli Jamun | D41: Desi Fruits | E41: Fruiting Trees | F41: Desi | G41: Yes | H41: No | O41: 450 | P41: 315 | Q41: 150 | T41: 0 | V41: Out of Stock | Y41: 20 | Z41: 20 | AA41: =IF(AND(N(Y41)>0,N(Z41)>0),ROUND(43560/(Y41*Z41),0),"") | AB41: 20ft x 20ft | AC41: Open sun | AE41: 20°C to 40 °C | AF41: Big tree | AG41: 2 years | AH41: 60Kg to 70Kg | AI41: May to August | AJ41: 50gm to 100gm | AR41: https://hasiruagro.com/wp-content/uploads/2023/08/Bhadoli-JamunFruit-image-Hasiruagro.jpg
...

Sheet Input Products
A1: Input Products
A2: Compost, vermicompost, biochar, seeds, liquid fertiliser, bio-pesticide. One row per pack size.
A4: SKU | B4: Product Name | C4: Kannada Name | D4: Category | E4: Pack Size | F4: Unit (kg / L / g / packet) | G4: Pack Weight (kg) | H4: Regular Price (Rs) | I4: Offer Price (Rs) | J4: Current Stock | K4: Low Stock Alert at | L4: Availability | M4: HSN Code | N4: GST % | O4: Short Description | P4: How to Use / Dosage | Q4: Recommended with which plants / models | R4: Best Seller? | S4: Image available? | T4: Notes
D5: Compost
D6: Vermicompost
D7: Biochar
D8: Seeds
D9: Liquid Fertiliser
D10: Bio-Pesticide

Sheet Recommendation Models
A1: Recommendation Models (Help Me Choose)
A2: For each model, list the plants and their role. The site scales the 36 x 36 ft block to the customer's land size.
A4: Model | B4: Short description for customers | C4: Plant density (plants per 36 x 36 ft) | D4: Plants per acre | E4: Row pattern in 36 x 36 ft (e.g. M o X o X o M) | F4: Legend (what M / o / X mean) | G4: Min land size | H4: Planting video URL | I4: Notes
A5: Commercial
A6: Food Forest
A7: Miyawaki
A11: Plants in each model
A12: Model | B12: Plant Name (as in Plants tab) | C12: Category | D12: Role (Main / Host / Biomass) | E12: Layer | F12: Spacing L (ft) | G12: Spacing W (ft) | H12: Qty per 36 x 36 ft | I12: Qty per acre (auto) | J12: Swap options (alternative plants) | K12: Vermicompost per plant (kg) | L12: Biochar per plant (kg) | M12: Notes
A13: Commercial | I13: =IF(N(H13)>0,ROUND(H13*43560/1296,0),"")
A14: Food Forest | I14: =IF(N(H14)>0,ROUND(H14*43560/1296,0),"")
A15: Miyawaki | I15: =IF(N(H15)>0,ROUND(H15*43560/1296,0),"")
I16: =IF(N(H16)>0,ROUND(H16*43560/1296,0),"")
I17: =IF(N(H17)>0,ROUND(H17*43560/1296,0),"")
I18: =IF(N(H18)>0,ROUND(H18*43560/1296,0),"")
I19: =IF(N(H19)>0,ROUND(H19*43560/1296,0),"")
I20: =IF(N(H20)>0,ROUND(H20*43560/1296,0),"")
I21: =IF(N(H21)>0,ROUND(H21*43560/1296,0),"")
I22: =IF(N(H22)>0,ROUND(H22*43560/1296,0),"")
I23: =IF(N(H23)>0,ROUND(H23*43560/1296,0),"")
I24: =IF(N(H24)>0,ROUND(H24*43560/1296,0),"")
I25: =IF(N(H25)>0,ROUND(H25*43560/1296,0),"")
I26: =IF(N(H26)>0,ROUND(H26*43560/1296,0),"")
I27: =IF(N(H27)>0,ROUND(H27*43560/1296,0),"")
... I72: =IF(N(H72)>0,ROUND(H72*43560/1296,0),"")

Sheet Calculators
A1: Calculator Formulas
A2: Our proposed formula is shown. Please confirm or replace it in the yellow column.
A4: Calculator | B4: Where used | C4: Proposed formula (WODO) | D4: Inputs the customer enters | E4: Hasiru Agro formula / correction | F4: Example to test | G4: Approved?
A5: Plants per acre | B5: Home, Shop (floating) | C5: Plants per acre = 43,560 / (spacing L ft x spacing W ft). Optional: + buffer % for replacements. | D5: Spacing L and W (ft), or plant picked (auto-fills its spacing), land size | F5: 10 x 10 ft -> 436 plants/acre
A6: Buffer / mortality allowance | B6: Plant calculator | C6: Add X% extra plants for replacements (sketch shows '43,560 x 3 / 100'; is that a 3% allowance?). | D6: -
A7: Compost requirement | B7: Home compost calculator | C7: Compost kg = sum over plants (qty x compost kg per plant). | D7: Plants and quantities selected | F7: 500 plants -> ? kg
A8: Vermicompost requirement | B8: Recommendation page, Cart | C8: Vermicompost kg = sum (qty x kg per plant, by plant size/type). | D8: Plants selected | F8: 500 plants -> ? kg
A9: Biochar requirement | B9: Recommendation page, Cart | C9: Biochar kg = sum (qty x kg per plant). | D9: Plants selected | F9: 500 plants -> ? kg
A10: Seed requirement | B10: Recommendation page | C10: Seeds (g or packets) per acre or per 36 x 36 block, e.g. for ground cover / green manure. | D10: Land size, model
A11: Model scaling | B11: Help Me Choose | C11: Plants for land = qty per 36 x 36 ft block x (land sq ft / 1,296). | D11: Land size (acre or sq ft) | F11: 1 acre = 33.6 blocks
A12: Pack rounding | B12: Cart | C12: Input kg rounded up to whole packs (e.g. 112 kg -> 5 x 25 kg). | D12: -

Sheet Logistics
A1: Delivery, Truck Capacity and Packing
A2: Needed for the truck-capacity meter, delivery charges and packing charges.
A4: A. Vehicles
A5: Vehicle type | B5: Max weight (kg) | C5: Max plants (small saplings) | D5: Max plants (large / 6 ft+) | E5: Rate per km (Rs) | F5: Minimum charge (Rs) | G5: Notes
A6: Tata Ace / small pickup
A7: Bolero pickup
A8: 407 / mid truck
A9: Large truck
A13: B. Bengaluru scheduled delivery
A14: Setting | B14: Value | G14: Notes
A15: Delivery day(s) of week
A16: Order cut-off (day + time)
A17: Delivery charge (flat / slab)
A18: Free delivery above (Rs)
A19: PIN codes / areas covered
A20: Max distance from nursery (km)
A23: C. Outstation delivery
A24: Rule | B24: Value | G24: Notes
A25: Rate per km (Rs)
A26: Rate per kg (Rs)
A27: Minimum order for outstation (Rs / plants)
A28: States / districts served
A29: Delivery lead time (days)
A30: Shared truck / part-load allowed?
A31: Who pays tolls / loading?
A34: D. Packing charges
A35: Rule | B35: Value | G35: Notes
A36: Packing type (per order / per plant / per kg / by size)
A37: Rate
A38: Free packing above (Rs)
A39: Special packing for large plants
A40: Courier option for single plants?
A43: E. Nursery pickup
A44: Setting | B44: Value | G44: Notes
A45: Nursery address + Google Maps link
A46: Pickup days and timings
A47: Ready-for-pickup time after order
A48: Contact number for pickup

Sheet Content & Policies
A1: Content, Media and Policies Checklist
A2: Share files in a shared Google Drive folder and mark the status here.
A4: Item | B4: Used on | C4: Details needed | D4: Status | E4: Drive link / Notes
A5: Home banner image + headline | B5: Home | C5: 1-3 hero images (farm / nursery), headline idea. | D5: Pending
A6: Logos: UAS Dharwad, Startup India, MSME, others | B6: Home band, About | C6: High-res logos and approved wording ('Incubated by UAS Dharwad, recognised by Startup India'). | D6: Pending
A7: Proven results numbers | B7: Why Choose Us, Farm Dev | C7: Total acres developed, farms developed, clients, projects, plants planted (verified). Current site says 120+ farms, 850+ acres; please confirm. | D7: Pending
A8: Why Choose Us points | B8: Home, Why Choose Us | C8: Plant authenticity (how quality is ensured), domain expertise, delivery to farm. | D8: Pending
A9: About Us | B9: About | C9: Chemical-free approach, certified permaculture designer (certificate copy), vision, mission, team photos. | D9: Pending
A10: Testimonials | B10: Home | C10: Name, location, photo, review, rating (1-5), farm/project details. Minimum 6. | D10: Pending
A11: DIY / Learn-how videos | B11: Home, Recommendation | C11: YouTube links, title, category, which model it belongs to (Commercial / Food Forest / Miyawaki). | D11: Pending
A12: Our Work (projects) | B12: Farm Development | C12: Per project: photos, before/after, location, acres, scope of work. | D12: Pending
A13: Our Clients | B13: Farm Development | C13: Client name (permission to show), project type, location, acreage, work done. | D13: Pending
A14: Damage policy | B14: Checkout, footer, policy page | C14: Reporting window (e.g. 48 hours), photo/video proof, what is covered. | D14: Pending
A15: Replacement policy | B15: Checkout, footer, policy page | C15: When a replacement is given, timeline, delivery of replacement. | D15: Pending
A16: Cancellation / return policy | B16: Checkout, footer, policy page | C16: Confirmed: no cancellation or return. Any exception (e.g. order not dispatched)? | D16: Pending
... A25: Product photos | B25: Shop | C25: New photos for plants marked 'New Photo Needed?' = Yes, and all input products. | D25: Pending

Sheet Category Map
A1: Category Mapping (proposed)
A2: Old shop had 5 categories. The SRS asks for Timber / Fruiting / Other. Please approve or change.
A4: Old category | B4: No. of plants | C4: Proposed new category | D4: Proposed filter / sub-category | E4: Approved? / Change to
A5: Forestry | B5: =COUNTIF(Plants!D:D,A5) | C5: Timber Trees | D5: -
A6: Desi Fruits | B6: =COUNTIF(Plants!D:D,A6) | C6: Fruiting Trees | D6: Desi
A7: Exotic fruits | B7: =COUNTIF(Plants!D:D,A7) | C7: Fruiting Trees | D7: Exotic
A8: Spices | B8: =COUNTIF(Plants!D:D,A8) | C8: Other Plants | D8: Spices
A9: Plantation | B9: =COUNTIF(Plants!D:D,A9) | C9: Other Plants | D9: Plantation
A11: Input categories (new): Compost, Vermicompost, Biochar, Seeds, Liquid Fertiliser, Bio-Pesticide. Add more if needed.
